Workbook

Sheet Raw_Data
A1: Resource ID | B1: Service Name | C1: Usage Quantity | D1: Usage Unit | E1: Region/Zone | F1: CPU Utilization (%) | G1: Memory Utilization (%) | H1: Network Inbound Data (Bytes) | I1: Network Outbound Data (Bytes) | J1: Usage Start Date | K1: Usage End Date | L1: Cost per Quantity ($) | M1: Unrounded Cost ($) | N1: Rounded Cost ($) | O1: Total Cost (INR)
A2: res-ST6BAJ2N | B2: Cloud Dataproc | C2: 954.9843 | D2: Requests | E2: europe-north1 | F2: 92.72 | G2: 70.42 | H2: 77097035547 | I2: 82685933273 | J2: 45299.933 | K2: 45481.287 | L2: 5.24 | M2: 5004.12 | N2: 5004 | O2: 415332
A3: res-TYGNR0RV | B3: Pub/Sub | C3: 479.6348 | D3: GB | E3: europe-west1 | F3: 37.78 | G3: 46.8 | H3: 8239357017 | I3: 11351490561 | J3: 23-08-2024 09:18 | K3: 25-08-2024 07:26 | L3: 9.82 | M3: 4710.01 | N3: 4710 | O3: 390930
A4: res-S3I9C869 | B4: BigQuery | C4: 114.4129 | D4: GB | E4: southamerica-east1 | F4: 82.54 | G4: 59.47 | H4: 23358691883 | I4: 23450812120 | J4: 18-07-2024 11:13 | K4: 22-07-2024 00:45 | L4: 7.37 | M4: 843.22 | N4: 843 | O4: 69969
A5: res-1RY9BZ6G | B5: Cloud Endpoints | C5: 413.193 | D5: GB | E5: us-central1 | F5: 86.68 | G5: 97.63 | H5: 53404385778 | I5: 60780194484 | J5: 20-07-2024 00:15 | K5: 21-07-2024 10:16 | L5: 4.41 | M5: 1822.18 | N5: 1822 | O5: 151226
A6: res-S3HQYIZ2 | B6: Cloud Spanner | C6: 335.9892 | D6: GB | E6: asia-southeast1 | F6: 82.95 | G6: 21.58 | H6: 10795270461 | I6: 14161382061 | J6: 21-08-2024 21:25 | K6: 25-08-2024 00:21 | L6: 6.09 | M6: 2046.17 | N6: 2046 | O6: 169818
A7: res-MWGCR6VT | B7: Cloud Run | C7: 50.8 | D7: Hours | E7: europe-north1 | F7: 32.36 | G7: 95.15 | H7: 67970493743 | I7: 70311789173 | J7: 18-07-2024 03:07 | K7: 20-07-2024 05:55 | L7: 8.8 | M7: 447.04 | N7: 447 | O7: 37101
A8: res-FSWKHTQW | B8: Cloud CDN | C8: 333.6126 | D8: Requests | E8: europe-west1 | F8: 12.21 | G8: 62.31 | H8: 27515142149 | I8: 27664449839 | J8: 23-08-2024 11:39 | K8: 25-08-2024 11:08 | L8: 5.84 | M8: 1948.3 | N8: 1948 | O8: 161684
A9: res-S7I6Z6JD | B9: Cloud Run | C9: 49.5833 | D9: Hours | E9: asia-southeast1 | F9: 59.18 | G9: 6.07 | H9: 69079125950 | I9: 78552821117 | J9: 20-08-2024 13:23 | K9: 22-08-2024 14:58 | L9: 4.84 | M9: 239.98 | N9: 240 | O9: 19920
A10: res-U3CCWT2L | B10: Cloud VPN | C10: 384.7979 | D10: Requests | E10: northamerica-northeast1 | F10: 36.67 | G10: 9.41 | H10: 14639390405 | I10: 20917834831 | J10: 45511.816 | K10: 14-07-2024 04:02 | L10: 1.98 | M10: 761.9 | N10: 762 | O10: 63246
A11: res-4DX4UZEY | B11: Firestore | C11: 533.6245 | D11: Requests | E11: australia-southeast1 | F11: 96.4 | G11: 52.4 | H11: 72632018521 | I11: 72843203438 | J11: 45419.392 | K11: 45572.893 | L11: 5.08 | M11: 2710.81 | N11: 2711 | O11: 225013
A12: res-JAL9EY6P | B12: Compute Engine | C12: 78.7 | D12: Hours | E12: europe-west1 | F12: 68.28 | G12: 26.56 | H12: 60327278928 | I12: 66769681245 | J12: 45542.606 | K12: 45633.885 | L12: 4.89 | M12: 384.84 | N12: 385 | O12: 31955
A13: res-B4GZM2Q6 | B13: AI Platform | C13: 86.6333 | D13: Hours | E13: europe-west1 | F13: 12.91 | G13: 5.41 | H13: 92616000746 | I13: 99059500361 | J13: 14-08-2024 09:47 | K13: 18-08-2024 00:25 | L13: 9.23 | M13: 799.63 | N13: 800 | O13: 66400
A14: res-012HZFAA | B14: Cloud Interconnect | C14: 290.0492 | D14: Requests | E14: us-central1 | F14: 53.93 | G14: 14.51 | H14: 15213923507 | I14: 19106889929 | J14: 19-07-2024 19:26 | K14: 22-07-2024 13:56 | L14: 4.09 | M14: 1186.3 | N14: 1186 | O14: 98438
A15: res-ELZMGAPV | B15: Pub/Sub | C15: 96.9514 | D15: Requests | E15: asia-east1 | F15: 73.72 | G15: 1.94 | H15: 47714907583 | I15: 55324053975 | J15: 18-07-2024 12:56 | K15: 20-07-2024 21:28 | L15: 3.15 | M15: 305.4 | N15: 305 | O15: 25315
A16: res-XACLYR7O | B16: Cloud CDN | C16: 657.3878 | D16: Requests | E16: us-east1 | F16: 43.57 | G16: 32.42 | H16: 64719533732 | I16: 74457276259 | J16: 45358.985 | K16: 45511.274 | L16: 3.28 | M16: 2156.23 | N16: 2156 | O16: 178948
A17: res-O0Y1GSUY | B17: AI Platform | C17: 98.3833 | D17: Hours | E17: asia-east1 | F17: 47.61 | G17: 86.01 | H17: 14130706238 | I17: 23480009488 | J17: 20-08-2024 03:04 | K17: 24-08-2024 05:27 | L17: 7.71 | M17: 758.54 | N17: 759 | O17: 62997
A18: res-S3LT44XO | B18: Cloud Build | C18: 713.5354 | D18: GB | E18: asia-east1 | F18: 93.56 | G18: 2.89 | H18: 61053572660 | I18: 66456079011 | J18: 25-08-2024 21:20 | K18: 31-08-2024 12:24 | L18: 5.12 | M18: 3653.3 | N18: 3653 | O18: 303199
A19: res-4FELBDAQ | B19: Cloud Armor | C19: 609.9901 | D19: Requests | E19: us-east1 | F19: 98.66 | G19: 51.52 | H19: 70591459011 | I19: 75043755268 | J19: 45480.036 | K19: 45542.574 | L19: 4.92 | M19: 3001.15 | N19: 3001 | O19: 249083
A20: res-8DBLI7MV | B20: Pub/Sub | C20: 61.3889 | D20: Requests | E20: asia-southeast1 | F20: 20.25 | G20: 49.89 | H20: 24459345122 | I20: 30238120394 | J20: 28-08-2024 09:37 | K20: 29-08-2024 17:30 | L20: 7.68 | M20: 471.47 | N20: 471 | O20: 39093
A21: res-KI6SEH8K | B21: Cloud VPN | C21: 194.6074 | D21: GB | E21: southamerica-east1 | F21: 71.48 | G21: 83.84 | H21: 50023921405 | I21: 52243912598 | J21: 45480.511 | K21: 45603.082 | L21: 7.04 | M21: 1370.04 | N21: 1370 | O21: 113710
A22: res-QTQQHAC7 | B22: Pub/Sub | C22: 590.1037 | D22: Requests | E22: southamerica-east1 | F22: 55.53 | G22: 76.7 | H22: 27785646604 | I22: 34873445199 | J22: 19-08-2024 07:29 | K22: 21-08-2024 09:41 | L22: 8.18 | M22: 4827.05 | N22: 4827 | O22: 400641
A23: res-4F4ZI2VT | B23: Firestore | C23: 152.1866 | D23: Requests | E23: australia-southeast1 | F23: 78.9 | G23: 60.38 | H23: 31595229818 | I23: 32905735415 | J23: 17-07-2024 20:20 | K23: 22-07-2024 08:13 | L23: 7.5 | M23: 1141.4 | N23: 1141 | O23: 94703
A24: res-EJ3TCI72 | B24: Compute Engine | C24: 90.7333 | D24: Hours | E24: northamerica-northeast1 | F24: 22.41 | G24: 61.79 | H24: 35788463783 | I24: 41202319167 | J24: 45420.554 | K24: 45543.335 | L24: 8.75 | M24: 793.92 | N24: 794 | O24: 65902
A25: res-27V25S4F | B25: Cloud VPN | C25: 389.9843 | D25: Requests | E25: us-central1 | F25: 97.47 | G25: 35.99 | H25: 96990383791 | I25: 101187000000 | J25: 17-08-2024 01:17 | K25: 19-08-2024 18:27 | L25: 1.92 | M25: 748.77 | N25: 749 | O25: 62167
A26: res-T91EICVM | B26: Cloud Load Balancing | C26: 389.6408 | D26: GB | E26: southamerica-east1 | F26: 65.57 | G26: 42.91 | H26: 31182295135 | I26: 38901764033 | J26: 45633.387 | K26: 17-07-2024 02:28 | L26: 8.26 | M26: 3218.43 | N26: 3218 | O26: 267094
A27: res-251A50KH | B27: Cloud Armor | C27: 902.3603 | D27: GB | E27: europe-north1 | F27: 27.7 | G27: 72.18 | H27: 75263901953 | I27: 80604527913 | J27: 23-08-2024 17:18 | K27: 29-08-2024 07:02 | L27: 6.25 | M27: 5639.75 | N27: 5640 | O27: 468120
A28: res-3JSZVG7Z | B28: Cloud Spanner | C28: 355.828 | D28: GB | E28: europe-west3 | F28: 89.39 | G28: 91.02 | H28: 84041157244 | I28: 92553952311 | J28: 26-08-2024 19:31 | K28: 29-08-2024 04:27 | L28: 5.17 | M28: 1839.63 | N28: 1840 | O28: 152720
A29: res-5O0LZKYC | B29: BigQuery | C29: 477.7508 | D29: Requests | E29: europe-north1 | F29: 63.32 | G29: 46.75 | H29: 88256196324 | I29: 95036019889 | J29: 45298.827 | K29: 45389.892 | L29: 7.49 | M29: 3578.35 | N29: 3578 | O29: 296974
A30: res-PGHLRRI4 | B30: Cloud Load Balancing | C30: 31.5518 | D30: Requests | E30: northamerica-northeast1 | F30: 62.15 | G30: 16.46 | H30: 54485062086 | I30: 62813003941 | J30: 45573.712 | K30: 15-08-2024 11:52 | L30: 8.65 | M30: 272.92 | N30: 273 | O30: 22659
A31: res-E5DZLWUA | B31: Dataflow | C31: 24.5167 | D31: Hours | E31: northamerica-northeast1 | F31: 63.68 | G31: 9.91 | H31: 34927527769 | I31: 44683895186 | J31: 27-08-2024 04:52 | K31: 28-08-2024 05:23 | L31: 7.74 | M31: 189.76 | N31: 190 | O31: 15770
A32: res-A6LFJNRY | B32: Compute Engine | C32: 85.0167 | D32: Hours | E32: southamerica-east1 | F32: 67.5 | G32: 76.78 | H32: 87269231137 | I32: 92709161595 | J32: 16-08-2024 00:18 | K32: 19-08-2024 13:19 | L32: 9.97 | M32: 847.62 | N32: 848 | O32: 70384
A33: res-CWFW5Z7I | B33: Cloud Dataproc | C33: 832.1664 | D33: Requests | E33: australia-southeast1 | F33: 23.65 | G33: 80.19 | H33: 93395407276 | I33: 102343000000 | J33: 26-08-2024 16:24 | K33: 31-08-2024 13:07 | L33: 5.91 | M33: 4918.1 | N33: 4918 | O33: 408194
A34: res-UEL2KJBD | B34: Cloud VPC | C34: 298.0653 | D34: GB | E34: us-west1 | F34: 66.82 | G34: 57.94 | H34: 24527235493 | I34: 26241930001 | J34: 45329.524 | K34: 45419.678 | L34: 7.34 | M34: 2187.8 | N34: 2188 | O34: 181604
A35: res-2NWIUO2C | B35: Cloud Load Balancing | C35: 868.8778 | D35: Requests | E35: asia-east1 | F35: 72.08 | G35: 28.06 | H35: 13159648227 | I35: 16566379456 | J35: 14-07-2024 17:48 | K35: 16-07-2024 23:28 | L35: 2.33 | M35: 2024.49 | N35: 2024 | O35: 167992
A36: res-TDYG7ESV | B36: Cloud NAT | C36: 306.7861 | D36: GB | E36: europe-north1 | F36: 19.59 | G36: 95.71 | H36: 98160908124 | I36: 106232000000 | J36: 45572.969 | K36: 45633.119 | L36: 8.51 | M36: 2610.75 | N36: 2611 | O36: 216713
A37: res-66L7XN4J | B37: AI Platform | C37: 31.9333 | D37: Hours | E37: europe-west1 | F37: 5.7 | G37: 31.59 | H37: 35137713111 | I37: 43813630384 | J37: 29-07-2024 06:08 | K37: 30-07-2024 14:04 | L37: 1.05 | M37: 33.53 | N37: 34 | O37: 2822
A38: res-SG6WQFX8 | B38: Cloud Armor | C38: 715.0198 | D38: GB | E38: us-west1 | F38: 44.97 | G38: 13.16 | H38: 47790743712 | I38: 50699817640 | J38: 14-07-2024 09:21 | K38: 18-07-2024 20:13 | L38: 3.29 | M38: 2352.42 | N38: 2352 | O38: 195216
A39: res-6EL50YPV | B39: Cloud CDN | C39: 749.8858 | D39: GB | E39: europe-north1 | F39: 84.06 | G39: 47.12 | H39: 58205533146 | I39: 63495177785 | J39: 16-08-2024 20:04 | K39: 21-08-2024 12:08 | L39: 2.03 | M39: 1522.27 | N39: 1522 | O39: 126326
A40: res-ALHVTEHO | B40: Kubernetes Engine | C40: 110.3167 | D40: Hours | E40: us-east1 | F40: 49.67 | G40: 26.17 | H40: 79950895147 | I40: 87873607051 | J40: 45359.415 | K40: 45512.011 | L40: 7.61 | M40: 839.51 | N40: 840 | O40: 69720
...

Sheet Cleaned_Data
A1: {=Raw_Data!A:O} -> Resource ID | B1: Service Name | C1: Usage Quantity | D1: Usage Unit | E1: Region/Zone | F1: CPU Utilization (%) | G1: Memory Utilization (%) | H1: Network Inbound Data (Bytes) | I1: Network Outbound Data (Bytes) | J1: Usage Start Date | K1: Usage End Date | L1: Cost per Quantity ($) | M1: Unrounded Cost ($) | N1: Rounded Cost ($) | O1: Total Cost (INR) | P1: Duration Hours | Q1: CPU Status | R1: Memory Status | S1: Network Total (GB) | T1: Cost Tier | U1: Efficiency Score
A2: res-ST6BAJ2N | B2: Cloud Dataproc | C2: 954.9843 | D2: Requests | E2: europe-north1 | F2: 92.72 | G2: 70.42 | H2: 77097035547 | I2: 82685933273 | J2: 45299.933 | K2: 45481.287 | L2: 5.24 | M2: 5004.12 | N2: 5004 | O2: 415332 | P2: =((DATE(MID(K2,7,4),MID(K2,4,2),LEFT(K2,2))+TIMEVALUE(RIGHT(K2,LEN(K2)-11)))-(DATE(MID(J2,7,4),MID(J2,4,2),LEFT(J2,2))+TIMEVALUE(RIGHT(J2,LEN(J2)-11))))*24 -> 128.5 | Q2: =IF(F2<30,"Underutilized",IF(F2<70,"Normal","High")) -> High | R2: =IF(G2<40,"Underutilized",IF(G2<75,"Normal","High")) -> Normal | S2: =(H2+I2)/1073741824 -> 148.80949 | T2: =IF(O2>AVERAGE($O$2:$O$500),"High Cost","Normal Cost") -> High Cost | U2: =((F2+G2)/2)/(O2/100) -> 0.01963971
A3: res-TYGNR0RV | B3: Pub/Sub | C3: 479.6348 | D3: GB | E3: europe-west1 | F3: 37.78 | G3: 46.8 | H3: 8239357017 | I3: 11351490561 | J3: 23-08-2024 09:18 | K3: 25-08-2024 07:26 | L3: 9.82 | M3: 4710.01 | N3: 4710 | O3: 390930 | P3: =((DATE(MID(K3,7,4),MID(K3,4,2),LEFT(K3,2))+TIMEVALUE(RIGHT(K3,LEN(K3)-11)))-(DATE(MID(J3,7,4),MID(J3,4,2),LEFT(J3,2))+TIMEVALUE(RIGHT(J3,LEN(J3)-11))))*24 -> 46.133333 | Q3: =IF(F3<30,"Underutilized",IF(F3<70,"Normal","High")) -> Normal | R3: =IF(G3<40,"Underutilized",IF(G3<75,"Normal","High")) -> Normal | S3: =(H3+I3)/1073741824 -> 18.245399 | T3: =IF(O3>AVERAGE($O$2:$O$500),"High Cost","Normal Cost") -> High Cost | U3: =((F3+G3)/2)/(O3/100) -> 0.010817793
A4: res-S3I9C869 | B4: BigQuery | C4: 114.4129 | D4: GB | E4: southamerica-east1 | F4: 82.54 | G4: 59.47 | H4: 23358691883 | I4: 23450812120 | J4: 18-07-2024 11:13 | K4: 22-07-2024 00:45 | L4: 7.37 | M4: 843.22 | N4: 843 | O4: 69969 | P4: =((DATE(MID(K4,7,4),MID(K4,4,2),LEFT(K4,2))+TIMEVALUE(RIGHT(K4,LEN(K4)-11)))-(DATE(MID(J4,7,4),MID(J4,4,2),LEFT(J4,2))+TIMEVALUE(RIGHT(J4,LEN(J4)-11))))*24 -> 85.533333 | Q4: =IF(F4<30,"Underutilized",IF(F4<70,"Normal","High")) -> High | R4: =IF(G4<40,"Underutilized",IF(G4<75,"Normal","High")) -> Normal | S4: =(H4+I4)/1073741824 -> 43.594748 | T4: =IF(O4>AVERAGE($O$2:$O$500),"High Cost","Normal Cost") -> Normal Cost | U4: =((F4+G4)/2)/(O4/100) -> 0.10148066
A5: res-1RY9BZ6G | B5: Cloud Endpoints | C5: 413.193 | D5: GB | E5: us-central1 | F5: 86.68 | G5: 97.63 | H5: 53404385778 | I5: 60780194484 | J5: 20-07-2024 00:15 | K5: 21-07-2024 10:16 | L5: 4.41 | M5: 1822.18 | N5: 1822 | O5: 151226 | P5: =((DATE(MID(K5,7,4),MID(K5,4,2),LEFT(K5,2))+TIMEVALUE(RIGHT(K5,LEN(K5)-11)))-(DATE(MID(J5,7,4),MID(J5,4,2),LEFT(J5,2))+TIMEVALUE(RIGHT(J5,LEN(J5)-11))))*24 -> 34.016667 | Q5: =IF(F5<30,"Underutilized",IF(F5<70,"Normal","High")) -> High | R5: =IF(G5<40,"Underutilized",IF(G5<75,"Normal","High")) -> High | S5: =(H5+I5)/1073741824 -> 106.34268 | T5: =IF(O5>AVERAGE($O$2:$O$500),"High Cost","Normal Cost") -> Normal Cost | U5: =((F5+G5)/2)/(O5/100) -> 0.060938595
A6: res-S3HQYIZ2 | B6: Cloud Spanner | C6: 335.9892 | D6: GB | E6: asia-southeast1 | F6: 82.95 | G6: 21.58 | H6: 10795270461 | I6: 14161382061 | J6: 21-08-2024 21:25 | K6: 25-08-2024 00:21 | L6: 6.09 | M6: 2046.17 | N6: 2046 | O6: 169818 | P6: =((DATE(MID(K6,7,4),MID(K6,4,2),LEFT(K6,2))+TIMEVALUE(RIGHT(K6,LEN(K6)-11)))-(DATE(MID(J6,7,4),MID(J6,4,2),LEFT(J6,2))+TIMEVALUE(RIGHT(J6,LEN(J6)-11))))*24 -> 74.933333 | Q6: =IF(F6<30,"Underutilized",IF(F6<70,"Normal","High")) -> High | R6: =IF(G6<40,"Underutilized",IF(G6<75,"Normal","High")) -> Underutilized | S6: =(H6+I6)/1073741824 -> 23.242694 | T6: =IF(O6>AVERAGE($O$2:$O$500),"High Cost","Normal Cost") -> Normal Cost | U6: =((F6+G6)/2)/(O6/100) -> 0.030777067
A7: res-MWGCR6VT | B7: Cloud Run | C7: 50.8 | D7: Hours | E7: europe-north1 | F7: 32.36 | G7: 95.15 | H7: 67970493743 | I7: 70311789173 | J7: 18-07-2024 03:07 | K7: 20-07-2024 05:55 | L7: 8.8 | M7: 447.04 | N7: 447 | O7: 37101 | P7: =((DATE(MID(K7,7,4),MID(K7,4,2),LEFT(K7,2))+TIMEVALUE(RIGHT(K7,LEN(K7)-11)))-(DATE(MID(J7,7,4),MID(J7,4,2),LEFT(J7,2))+TIMEVALUE(RIGHT(J7,LEN(J7)-11))))*24 -> 50.8 | Q7: =IF(F7<30,"Underutilized",IF(F7<70,"Normal","High")) -> Normal | R7: =IF(G7<40,"Underutilized",IF(G7<75,"Normal","High")) -> High | S7: =(H7+I7)/1073741824 -> 128.78541 | T7: =IF(O7>AVERAGE($O$2:$O$500),"High Cost","Normal Cost") -> Normal Cost | U7: =((F7+G7)/2)/(O7/100) -> 0.17184173
A8: res-FSWKHTQW | B8: Cloud CDN | C8: 333.6126 | D8: Requests | E8: europe-west1 | F8: 12.21 | G8: 62.31 | H8: 27515142149 | I8: 27664449839 | J8: 23-08-2024 11:39 | K8: 25-08-2024 11:08 | L8: 5.84 | M8: 1948.3 | N8: 1948 | O8: 161684 | P8: =((DATE(MID(K8,7,4),MID(K8,4,2),LEFT(K8,2))+TIMEVALUE(RIGHT(K8,LEN(K8)-11)))-(DATE(MID(J8,7,4),MID(J8,4,2),LEFT(J8,2))+TIMEVALUE(RIGHT(J8,LEN(J8)-11))))*24 -> 47.483333 | Q8: =IF(F8<30,"Underutilized",IF(F8<70,"Normal","High")) -> Underutilized | R8: =IF(G8<40,"Underutilized",IF(G8<75,"Normal","High")) -> Normal | S8: =(H8+I8)/1073741824 -> 51.39 | T8: =IF(O8>AVERAGE($O$2:$O$500),"High Cost","Normal Cost") -> Normal Cost | U8: =((F8+G8)/2)/(O8/100) -> 0.023044952
A9: res-S7I6Z6JD | B9: Cloud Run | C9: 49.5833 | D9: Hours | E9: asia-southeast1 | F9: 59.18 | G9: 6.07 | H9: 69079125950 | I9: 78552821117 | J9: 20-08-2024 13:23 | K9: 22-08-2024 14:58 | L9: 4.84 | M9: 239.98 | N9: 240 | O9: 19920 | P9: =((DATE(MID(K9,7,4),MID(K9,4,2),LEFT(K9,2))+TIMEVALUE(RIGHT(K9,LEN(K9)-11)))-(DATE(MID(J9,7,4),MID(J9,4,2),LEFT(J9,2))+TIMEVALUE(RIGHT(J9,LEN(J9)-11))))*24 -> 49.583333 | Q9: =IF(F9<30,"Underutilized",IF(F9<70,"Normal","High")) -> Normal | R9: =IF(G9<40,"Underutilized",IF(G9<75,"Normal","High")) -> Underutilized | S9: =(H9+I9)/1073741824 -> 137.49296 | T9: =IF(O9>AVERAGE($O$2:$O$500),"High Cost","Normal Cost") -> Normal Cost | U9: =((F9+G9)/2)/(O9/100) -> 0.16378012
A10: res-U3CCWT2L | B10: Cloud VPN | C10: 384.7979 | D10: Requests | E10: northamerica-northeast1 | F10: 36.67 | G10: 9.41 | H10: 14639390405 | I10: 20917834831 | J10: 45511.816 | K10: 14-07-2024 04:02 | L10: 1.98 | M10: 761.9 | N10: 762 | O10: 63246 | P10: =((DATE(MID(K10,7,4),MID(K10,4,2),LEFT(K10,2))+TIMEVALUE(RIGHT(K10,LEN(K10)-11)))-(DATE(MID(J10,7,4),MID(J10,4,2),LEFT(J10,2))+TIMEVALUE(RIGHT(J10,LEN(J10)-11))))*24 -> 128.45 | Q10: =IF(F10<30,"Underutilized",IF(F10<70,"Normal","High")) -> Normal | R10: =IF(G10<40,"Underutilized",IF(G10<75,"Normal","High")) -> Underutilized | S10: =(H10+I10)/1073741824 -> 33.115247 | T10: =IF(O10>AVERAGE($O$2:$O$500),"High Cost","Normal Cost") -> Normal Cost | U10: =((F10+G10)/2)/(O10/100) -> 0.036429181
A11: res-4DX4UZEY | B11: Firestore | C11: 533.6245 | D11: Requests | E11: australia-southeast1 | F11: 96.4 | G11: 52.4 | H11: 72632018521 | I11: 72843203438 | J11: 45419.392 | K11: 45572.893 | L11: 5.08 | M11: 2710.81 | N11: 2711 | O11: 225013 | P11: =((DATE(MID(K11,7,4),MID(K11,4,2),LEFT(K11,2))+TIMEVALUE(RIGHT(K11,LEN(K11)-11)))-(DATE(MID(J11,7,4),MID(J11,4,2),LEFT(J11,2))+TIMEVALUE(RIGHT(J11,LEN(J11)-11))))*24 -> 132.01667 | Q11: =IF(F11<30,"Underutilized",IF(F11<70,"Normal","High")) -> High | R11: =IF(G11<40,"Underutilized",IF(G11<75,"Normal","High")) -> Normal | S11: =(H11+I11)/1073741824 -> 135.48436 | T11: =IF(O11>AVERAGE($O$2:$O$500),"High Cost","Normal Cost") -> High Cost | U11: =((F11+G11)/2)/(O11/100) -> 0.033064756
A12: res-JAL9EY6P | B12: Compute Engine | C12: 78.7 | D12: Hours | E12: europe-west1 | F12: 68.28 | G12: 26.56 | H12: 60327278928 | I12: 66769681245 | J12: 45542.606 | K12: 45633.885 | L12: 4.89 | M12: 384.84 | N12: 385 | O12: 31955 | P12: =((DATE(MID(K12,7,4),MID(K12,4,2),LEFT(K12,2))+TIMEVALUE(RIGHT(K12,LEN(K12)-11)))-(DATE(MID(J12,7,4),MID(J12,4,2),LEFT(J12,2))+TIMEVALUE(RIGHT(J12,LEN(J12)-11))))*24 -> 78.7 | Q12: =IF(F12<30,"Underutilized",IF(F12<70,"Normal","High")) -> Normal | R12: =IF(G12<40,"Underutilized",IF(G12<75,"Normal","High")) -> Underutilized | S12: =(H12+I12)/1073741824 -> 118.36827 | T12: =IF(O12>AVERAGE($O$2:$O$500),"High Cost","Normal Cost") -> Normal Cost | U12: =((F12+G12)/2)/(O12/100) -> 0.14839618
A13: res-B4GZM2Q6 | B13: AI Platform | C13: 86.6333 | D13: Hours | E13: europe-west1 | F13: 12.91 | G13: 5.41 | H13: 92616000746 | I13: 99059500361 | J13: 14-08-2024 09:47 | K13: 18-08-2024 00:25 | L13: 9.23 | M13: 799.63 | N13: 800 | O13: 66400 | P13: =((DATE(MID(K13,7,4),MID(K13,4,2),LEFT(K13,2))+TIMEVALUE(RIGHT(K13,LEN(K13)-11)))-(DATE(MID(J13,7,4),MID(J13,4,2),LEFT(J13,2))+TIMEVALUE(RIGHT(J13,LEN(J13)-11))))*24 -> 86.633333 | Q13: =IF(F13<30,"Underutilized",IF(F13<70,"Normal","High")) -> Underutilized | R13: =IF(G13<40,"Underutilized",IF(G13<75,"Normal","High")) -> Underutilized | S13: =(H13+I13)/1073741824 -> 178.51172 | T13: =IF(O13>AVERAGE($O$2:$O$500),"High Cost","Normal Cost") -> Normal Cost | U13: =((F13+G13)/2)/(O13/100) -> 0.013795181
A14: res-012HZFAA | B14: Cloud Interconnect | C14: 290.0492 | D14: Requests | E14: us-central1 | F14: 53.93 | G14: 14.51 | H14: 15213923507 | I14: 19106889929 | J14: 19-07-2024 19:26 | K14: 22-07-2024 13:56 | L14: 4.09 | M14: 1186.3 | N14: 1186 | O14: 98438 | P14: =((DATE(MID(K14,7,4),MID(K14,4,2),LEFT(K14,2))+TIMEVALUE(RIGHT(K14,LEN(K14)-11)))-(DATE(MID(J14,7,4),MID(J14,4,2),LEFT(J14,2))+TIMEVALUE(RIGHT(J14,LEN(J14)-11))))*24 -> 66.5 | Q14: =IF(F14<30,"Underutilized",IF(F14<70,"Normal","High")) -> Normal | R14: =IF(G14<40,"Underutilized",IF(G14<75,"Normal","High")) -> Underutilized | S14: =(H14+I14)/1073741824 -> 31.963748 | T14: =IF(O14>AVERAGE($O$2:$O$500),"High Cost","Normal Cost") -> Normal Cost | U14: =((F14+G14)/2)/(O14/100) -> 0.034762998
A15: res-ELZMGAPV | B15: Pub/Sub | C15: 96.9514 | D15: Requests | E15: asia-east1 | F15: 73.72 | G15: 1.94 | H15: 47714907583 | I15: 55324053975 | J15: 18-07-2024 12:56 | K15: 20-07-2024 21:28 | L15: 3.15 | M15: 305.4 | N15: 305 | O15: 25315 | P15: =((DATE(MID(K15,7,4),MID(K15,4,2),LEFT(K15,2))+TIMEVALUE(RIGHT(K15,LEN(K15)-11)))-(DATE(MID(J15,7,4),MID(J15,4,2),LEFT(J15,2))+TIMEVALUE(RIGHT(J15,LEN(J15)-11))))*24 -> 56.533333 | Q15: =IF(F15<30,"Underutilized",IF(F15<70,"Normal","High")) -> High | R15: =IF(G15<40,"Underutilized",IF(G15<75,"Normal","High")) -> Underutilized | S15: =(H15+I15)/1073741824 -> 95.962511 | T15: =IF(O15>AVERAGE($O$2:$O$500),"High Cost","Normal Cost") -> Normal Cost | U15: =((F15+G15)/2)/(O15/100) -> 0.14943709
A16: res-XACLYR7O | B16: Cloud CDN | C16: 657.3878 | D16: Requests | E16: us-east1 | F16: 43.57 | G16: 32.42 | H16: 64719533732 | I16: 74457276259 | J16: 45358.985 | K16: 45511.274 | L16: 3.28 | M16: 2156.23 | N16: 2156 | O16: 178948 | P16: =((DATE(MID(K16,7,4),MID(K16,4,2),LEFT(K16,2))+TIMEVALUE(RIGHT(K16,LEN(K16)-11)))-(DATE(MID(J16,7,4),MID(J16,4,2),LEFT(J16,2))+TIMEVALUE(RIGHT(J16,LEN(J16)-11))))*24 -> 102.93333 | Q16: =IF(F16<30,"Underutilized",IF(F16<70,"Normal","High")) -> Normal | R16: =IF(G16<40,"Underutilized",IF(G16<75,"Normal","High")) -> Underutilized | S16: =(H16+I16)/1073741824 -> 129.6185 | T16: =IF(O16>AVERAGE($O$2:$O$500),"High Cost","Normal Cost") -> High Cost | U16: =((F16+G16)/2)/(O16/100) -> 0.021232425
A17: res-O0Y1GSUY | B17: AI Platform | C17: 98.3833 | D17: Hours | E17: asia-east1 | F17: 47.61 | G17: 86.01 | H17: 14130706238 | I17: 23480009488 | J17: 20-08-2024 03:04 | K17: 24-08-2024 05:27 | L17: 7.71 | M17: 758.54 | N17: 759 | O17: 62997 | P17: =((DATE(MID(K17,7,4),MID(K17,4,2),LEFT(K17,2))+TIMEVALUE(RIGHT(K17,LEN(K17)-11)))-(DATE(MID(J17,7,4),MID(J17,4,2),LEFT(J17,2))+TIMEVALUE(RIGHT(J17,LEN(J17)-11))))*24 -> 98.383333 | Q17: =IF(F17<30,"Underutilized",IF(F17<70,"Normal","High")) -> Normal | R17: =IF(G17<40,"Underutilized",IF(G17<75,"Normal","High")) -> High | S17: =(H17+I17)/1073741824 -> 35.027709 | T17: =IF(O17>AVERAGE($O$2:$O$500),"High Cost","Normal Cost") -> Normal Cost | U17: =((F17+G17)/2)/(O17/100) -> 0.10605267
A18: res-S3LT44XO | B18: Cloud Build | C18: 713.5354 | D18: GB | E18: asia-east1 | F18: 93.56 | G18: 2.89 | H18: 61053572660 | I18: 66456079011 | J18: 25-08-2024 21:20 | K18: 31-08-2024 12:24 | L18: 5.12 | M18: 3653.3 | N18: 3653 | O18: 303199 | P18: =((DATE(MID(K18,7,4),MID(K18,4,2),LEFT(K18,2))+TIMEVALUE(RIGHT(K18,LEN(K18)-11)))-(DATE(MID(J18,7,4),MID(J18,4,2),LEFT(J18,2))+TIMEVALUE(RIGHT(J18,LEN(J18)-11))))*24 -> 135.06667 | Q18: =IF(F18<30,"Underutilized",IF(F18<70,"Normal","High")) -> High | R18: =IF(G18<40,"Underutilized",IF(G18<75,"Normal","High")) -> Underutilized | S18: =(H18+I18)/1073741824 -> 118.75262 | T18: =IF(O18>AVERAGE($O$2:$O$500),"High Cost","Normal Cost") -> High Cost | U18: =((F18+G18)/2)/(O18/100) -> 0.015905395
A19: res-4FELBDAQ | B19: Cloud Armor | C19: 609.9901 | D19: Requests | E19: us-east1 | F19: 98.66 | G19: 51.52 | H19: 70591459011 | I19: 75043755268 | J19: 45480.036 | K19: 45542.574 | L19: 4.92 | M19: 3001.15 | N19: 3001 | O19: 249083 | P19: =((DATE(MID(K19,7,4),MID(K19,4,2),LEFT(K19,2))+TIMEVALUE(RIGHT(K19,LEN(K19)-11)))-(DATE(MID(J19,7,4),MID(J19,4,2),LEFT(J19,2))+TIMEVALUE(RIGHT(J19,LEN(J19)-11))))*24 -> 60.9 | Q19: =IF(F19<30,"Underutilized",IF(F19<70,"Normal","High")) -> High | R19: =IF(G19<40,"Underutilized",IF(G19<75,"Normal","High")) -> Normal | S19: =(H19+I19)/1073741824 -> 135.63336 | T19: =IF(O19>AVERAGE($O$2:$O$500),"High Cost","Normal Cost") -> High Cost | U19: =((F19+G19)/2)/(O19/100) -> 0.030146578
A20: res-8DBLI7MV | B20: Pub/Sub | C20: 61.3889 | D20: Requests | E20: asia-southeast1 | F20: 20.25 | G20: 49.89 | H20: 24459345122 | I20: 30238120394 | J20: 28-08-2024 09:37 | K20: 29-08-2024 17:30 | L20: 7.68 | M20: 471.47 | N20: 471 | O20: 39093 | P20: =((DATE(MID(K20,7,4),MID(K20,4,2),LEFT(K20,2))+TIMEVALUE(RIGHT(K20,LEN(K20)-11)))-(DATE(MID(J20,7,4),MID(J20,4,2),LEFT(J20,2))+TIMEVALUE(RIGHT(J20,LEN(J20)-11))))*24 -> 31.883333 | Q20: =IF(F20<30,"Underutilized",IF(F20<70,"Normal","High")) -> Underutilized | R20: =IF(G20<40,"Underutilized",IF(G20<75,"Normal","High")) -> Normal | S20: =(H20+I20)/1073741824 -> 50.940984 | T20: =IF(O20>AVERAGE($O$2:$O$500),"High Cost","Normal Cost") -> Normal Cost | U20: =((F20+G20)/2)/(O20/100) -> 0.089709155
A21: res-KI6SEH8K | B21: Cloud VPN | C21: 194.6074 | D21: GB | E21: southamerica-east1 | F21: 71.48 | G21: 83.84 | H21: 50023921405 | I21: 52243912598 | J21: 45480.511 | K21: 45603.082 | L21: 7.04 | M21: 1370.04 | N21: 1370 | O21: 113710 | P21: =((DATE(MID(K21,7,4),MID(K21,4,2),LEFT(K21,2))+TIMEVALUE(RIGHT(K21,LEN(K21)-11)))-(DATE(MID(J21,7,4),MID(J21,4,2),LEFT(J21,2))+TIMEVALUE(RIGHT(J21,LEN(J21)-11))))*24 -> 85.7 | Q21: =IF(F21<30,"Underutilized",IF(F21<70,"Normal","High")) -> High | R21: =IF(G21<40,"Underutilized",IF(G21<75,"Normal","High")) -> High | S21: =(H21+I21)/1073741824 -> 95.244342 | T21: =IF(O21>AVERAGE($O$2:$O$500),"High Cost","Normal Cost") -> Normal Cost | U21: =((F21+G21)/2)/(O21/100) -> 0.068296544
A22: res-QTQQHAC7 | B22: Pub/Sub | C22: 590.1037 | D22: Requests | E22: southamerica-east1 | F22: 55.53 | G22: 76.7 | H22: 27785646604 | I22: 34873445199 | J22: 19-08-2024 07:29 | K22: 21-08-2024 09:41 | L22: 8.18 | M22: 4827.05 | N22: 4827 | O22: 400641 | P22: =((DATE(MID(K22,7,4),MID(K22,4,2),LEFT(K22,2))+TIMEVALUE(RIGHT(K22,LEN(K22)-11)))-(DATE(MID(J22,7,4),MID(J22,4,2),LEFT(J22,2))+TIMEVALUE(RIGHT(J22,LEN(J22)-11))))*24 -> 50.2 | Q22: =IF(F22<30,"Underutilized",IF(F22<70,"Normal","High")) -> Normal | R22: =IF(G22<40,"Underutilized",IF(G22<75,"Normal","High")) -> High | S22: =(H22+I22)/1073741824 -> 58.355827 | T22: =IF(O22>AVERAGE($O$2:$O$500),"High Cost","Normal Cost") -> High Cost | U22: =((F22+G22)/2)/(O22/100) -> 0.016502305
A23: res-4F4ZI2VT | B23: Firestore | C23: 152.1866 | D23: Requests | E23: australia-southeast1 | F23: 78.9 | G23: 60.38 | H23: 31595229818 | I23: 32905735415 | J23: 17-07-2024 20:20 | K23: 22-07-2024 08:13 | L23: 7.5 | M23: 1141.4 | N23: 1141 | O23: 94703 | P23: =((DATE(MID(K23,7,4),MID(K23,4,2),LEFT(K23,2))+TIMEVALUE(RIGHT(K23,LEN(K23)-11)))-(DATE(MID(J23,7,4),MID(J23,4,2),LEFT(J23,2))+TIMEVALUE(RIGHT(J23,LEN(J23)-11))))*24 -> 107.88333 | Q23: =IF(F23<30,"Underutilized",IF(F23<70,"Normal","High")) -> High | R23: =IF(G23<40,"Underutilized",IF(G23<75,"Normal","High")) -> Normal | S23: =(H23+I23)/1073741824 -> 60.071205 | T23: =IF(O23>AVERAGE($O$2:$O$500),"High Cost","Normal Cost") -> Normal Cost | U23: =((F23+G23)/2)/(O23/100) -> 0.073535157
A24: res-EJ3TCI72 | B24: Compute Engine | C24: 90.7333 | D24: Hours | E24: northamerica-northeast1 | F24: 22.41 | G24: 61.79 | H24: 35788463783 | I24: 41202319167 | J24: 45420.554 | K24: 45543.335 | L24: 8.75 | M24: 793.92 | N24: 794 | O24: 65902 | P24: =((DATE(MID(K24,7,4),MID(K24,4,2),LEFT(K24,2))+TIMEVALUE(RIGHT(K24,LEN(K24)-11)))-(DATE(MID(J24,7,4),MID(J24,4,2),LEFT(J24,2))+TIMEVALUE(RIGHT(J24,LEN(J24)-11))))*24 -> 90.733333 | Q24: =IF(F24<30,"Underutilized",IF(F24<70,"Normal","High")) -> Underutilized | R24: =IF(G24<40,"Underutilized",IF(G24<75,"Normal","High")) -> Normal | S24: =(H24+I24)/1073741824 -> 71.703254 | T24: =IF(O24>AVERAGE($O$2:$O$500),"High Cost","Normal Cost") -> Normal Cost | U24: =((F24+G24)/2)/(O24/100) -> 0.063882735
A25: res-27V25S4F | B25: Cloud VPN | C25: 389.9843 | D25: Requests | E25: us-central1 | F25: 97.47 | G25: 35.99 | H25: 96990383791 | I25: 101187000000 | J25: 17-08-2024 01:17 | K25: 19-08-2024 18:27 | L25: 1.92 | M25: 748.77 | N25: 749 | O25: 62167 | P25: =((DATE(MID(K25,7,4),MID(K25,4,2),LEFT(K25,2))+TIMEVALUE(RIGHT(K25,LEN(K25)-11)))-(DATE(MID(J25,7,4),MID(J25,4,2),LEFT(J25,2))+TIMEVALUE(RIGHT(J25,LEN(J25)-11))))*24 -> 65.166667 | Q25: =IF(F25<30,"Underutilized",IF(F25<70,"Normal","High")) -> High | R25: =IF(G25<40,"Underutilized",IF(G25<75,"Normal","High")) -> Underutilized | S25: =(H25+I25)/1073741824 -> 184.56707 | T25: =IF(O25>AVERAGE($O$2:$O$500),"High Cost","Normal Cost") -> Normal Cost | U25: =((F25+G25)/2)/(O25/100) -> 0.10733991
A26: res-T91EICVM | B26: Cloud Load Balancing | C26: 389.6408 | D26: GB | E26: southamerica-east1 | F26: 65.57 | G26: 42.91 | H26: 31182295135 | I26: 38901764033 | J26: 45633.387 | K26: 17-07-2024 02:28 | L26: 8.26 | M26: 3218.43 | N26: 3218 | O26: 267094 | P26: =((DATE(MID(K26,7,4),MID(K26,4,2),LEFT(K26,2))+TIMEVALUE(RIGHT(K26,LEN(K26)-11)))-(DATE(MID(J26,7,4),MID(J26,4,2),LEFT(J26,2))+TIMEVALUE(RIGHT(J26,LEN(J26)-11))))*24 -> 113.16667 | Q26: =IF(F26<30,"Underutilized",IF(F26<70,"Normal","High")) -> Normal | R26: =IF(G26<40,"Underutilized",IF(G26<75,"Normal","High")) -> Normal | S26: =(H26+I26)/1073741824 -> 65.270866 | T26: =IF(O26>AVERAGE($O$2:$O$500),"High Cost","Normal Cost") -> High Cost | U26: =((F26+G26)/2)/(O26/100) -> 0.020307457
A27: res-251A50KH | B27: Cloud Armor | C27: 902.3603 | D27: GB | E27: europe-north1 | F27: 27.7 | G27: 72.18 | H27: 75263901953 | I27: 80604527913 | J27: 23-08-2024 17:18 | K27: 29-08-2024 07:02 | L27: 6.25 | M27: 5639.75 | N27: 5640 | O27: 468120 | P27: =((DATE(MID(K27,7,4),MID(K27,4,2),LEFT(K27,2))+TIMEVALUE(RIGHT(K27,LEN(K27)-11)))-(DATE(MID(J27,7,4),MID(J27,4,2),LEFT(J27,2))+TIMEVALUE(RIGHT(J27,LEN(J27)-11))))*24 -> 133.73333 | Q27: =IF(F27<30,"Underutilized",IF(F27<70,"Normal","High")) -> Underutilized | R27: =IF(G27<40,"Underutilized",IF(G27<75,"Normal","High")) -> Normal | S27: =(H27+I27)/1073741824 -> 145.16379 | T27: =IF(O27>AVERAGE($O$2:$O$500),"High Cost","Normal Cost") -> High Cost | U27: =((F27+G27)/2)/(O27/100) -> 0.010668205
A28: res-3JSZVG7Z | B28: Cloud Spanner | C28: 355.828 | D28: GB | E28: europe-west3 | F28: 89.39 | G28: 91.02 | H28: 84041157244 | I28: 92553952311 | J28: 26-08-2024 19:31 | K28: 29-08-2024 04:27 | L28: 5.17 | M28: 1839.63 | N28: 1840 | O28: 152720 | P28: =((DATE(MID(K28,7,4),MID(K28,4,2),LEFT(K28,2))+TIMEVALUE(RIGHT(K28,LEN(K28)-11)))-(DATE(MID(J28,7,4),MID(J28,4,2),LEFT(J28,2))+TIMEVALUE(RIGHT(J28,LEN(J28)-11))))*24 -> 56.933333 | Q28: =IF(F28<30,"Underutilized",IF(F28<70,"Normal","High")) -> High | R28: =IF(G28<40,"Underutilized",IF(G28<75,"Normal","High")) -> High | S28: =(H28+I28)/1073741824 -> 164.46701 | T28: =IF(O28>AVERAGE($O$2:$O$500),"High Cost","Normal Cost") -> Normal Cost | U28: =((F28+G28)/2)/(O28/100) -> 0.05906561
A29: res-5O0LZKYC | B29: BigQuery | C29: 477.7508 | D29: Requests | E29: europe-north1 | F29: 63.32 | G29: 46.75 | H29: 88256196324 | I29: 95036019889 | J29: 45298.827 | K29: 45389.892 | L29: 7.49 | M29: 3578.35 | N29: 3578 | O29: 296974 | P29: =((DATE(MID(K29,7,4),MID(K29,4,2),LEFT(K29,2))+TIMEVALUE(RIGHT(K29,LEN(K29)-11)))-(DATE(MID(J29,7,4),MID(J29,4,2),LEFT(J29,2))+TIMEVALUE(RIGHT(J29,LEN(J29)-11))))*24 -> 73.55 | Q29: =IF(F29<30,"Underutilized",IF(F29<70,"Normal","High")) -> Normal | R29: =IF(G29<40,"Underutilized",IF(G29<75,"Normal","High")) -> Normal | S29: =(H29+I29)/1073741824 -> 170.70418 | T29: =IF(O29>AVERAGE($O$2:$O$500),"High Cost","Normal Cost") -> High Cost | U29: =((F29+G29)/2)/(O29/100) -> 0.018531925
A30: res-PGHLRRI4 | B30: Cloud Load Balancing | C30: 31.5518 | D30: Requests | E30: northamerica-northeast1 | F30: 62.15 | G30: 16.46 | H30: 54485062086 | I30: 62813003941 | J30: 45573.712 | K30: 15-08-2024 11:52 | L30: 8.65 | M30: 272.92 | N30: 273 | O30: 22659 | P30: =((DATE(MID(K30,7,4),MID(K30,4,2),LEFT(K30,2))+TIMEVALUE(RIGHT(K30,LEN(K30)-11)))-(DATE(MID(J30,7,4),MID(J30,4,2),LEFT(J30,2))+TIMEVALUE(RIGHT(J30,LEN(J30)-11))))*24 -> 114.78333 | Q30: =IF(F30<30,"Underutilized",IF(F30<70,"Normal","High")) -> Normal | R30: =IF(G30<40,"Underutilized",IF(G30<75,"Normal","High")) -> Underutilized | S30: =(H30+I30)/1073741824 -> 109.24234 | T30: =IF(O30>AVERAGE($O$2:$O$500),"High Cost","Normal Cost") -> Normal Cost | U30: =((F30+G30)/2)/(O30/100) -> 0.17346308
A31: res-E5DZLWUA | B31: Dataflow | C31: 24.5167 | D31: Hours | E31: northamerica-northeast1 | F31: 63.68 | G31: 9.91 | H31: 34927527769 | I31: 44683895186 | J31: 27-08-2024 04:52 | K31: 28-08-2024 05:23 | L31: 7.74 | M31: 189.76 | N31: 190 | O31: 15770 | P31: =((DATE(MID(K31,7,4),MID(K31,4,2),LEFT(K31,2))+TIMEVALUE(RIGHT(K31,LEN(K31)-11)))-(DATE(MID(J31,7,4),MID(J31,4,2),LEFT(J31,2))+TIMEVALUE(RIGHT(J31,LEN(J31)-11))))*24 -> 24.516667 | Q31: =IF(F31<30,"Underutilized",IF(F31<70,"Normal","High")) -> Normal | R31: =IF(G31<40,"Underutilized",IF(G31<75,"Normal","High")) -> Underutilized | S31: =(H31+I31)/1073741824 -> 74.143915 | T31: =IF(O31>AVERAGE($O$2:$O$500),"High Cost","Normal Cost") -> Normal Cost | U31: =((F31+G31)/2)/(O31/100) -> 0.23332276
A32: res-A6LFJNRY | B32: Compute Engine | C32: 85.0167 | D32: Hours | E32: southamerica-east1 | F32: 67.5 | G32: 76.78 | H32: 87269231137 | I32: 92709161595 | J32: 16-08-2024 00:18 | K32: 19-08-2024 13:19 | L32: 9.97 | M32: 847.62 | N32: 848 | O32: 70384 | P32: =((DATE(MID(K32,7,4),MID(K32,4,2),LEFT(K32,2))+TIMEVALUE(RIGHT(K32,LEN(K32)-11)))-(DATE(MID(J32,7,4),MID(J32,4,2),LEFT(J32,2))+TIMEVALUE(RIGHT(J32,LEN(J32)-11))))*24 -> 85.016667 | Q32: =IF(F32<30,"Underutilized",IF(F32<70,"Normal","High")) -> Normal | R32: =IF(G32<40,"Underutilized",IF(G32<75,"Normal","High")) -> High | S32: =(H32+I32)/1073741824 -> 167.61794 | T32: =IF(O32>AVERAGE($O$2:$O$500),"High Cost","Normal Cost") -> Normal Cost | U32: =((F32+G32)/2)/(O32/100) -> 0.10249489
A33: res-CWFW5Z7I | B33: Cloud Dataproc | C33: 832.1664 | D33: Requests | E33: australia-southeast1 | F33: 23.65 | G33: 80.19 | H33: 93395407276 | I33: 102343000000 | J33: 26-08-2024 16:24 | K33: 31-08-2024 13:07 | L33: 5.91 | M33: 4918.1 | N33: 4918 | O33: 408194 | P33: =((DATE(MID(K33,7,4),MID(K33,4,2),LEFT(K33,2))+TIMEVALUE(RIGHT(K33,LEN(K33)-11)))-(DATE(MID(J33,7,4),MID(J33,4,2),LEFT(J33,2))+TIMEVALUE(RIGHT(J33,LEN(J33)-11))))*24 -> 116.71667 | Q33: =IF(F33<30,"Underutilized",IF(F33<70,"Normal","High")) -> Underutilized | R33: =IF(G33<40,"Underutilized",IF(G33<75,"Normal","High")) -> High | S33: =(H33+I33)/1073741824 -> 182.2956 | T33: =IF(O33>AVERAGE($O$2:$O$500),"High Cost","Normal Cost") -> High Cost | U33: =((F33+G33)/2)/(O33/100) -> 0.012719442
A34: res-UEL2KJBD | B34: Cloud VPC | C34: 298.0653 | D34: GB | E34: us-west1 | F34: 66.82 | G34: 57.94 | H34: 24527235493 | I34: 26241930001 | J34: 45329.524 | K34: 45419.678 | L34: 7.34 | M34: 2187.8 | N34: 2188 | O34: 181604 | P34: =((DATE(MID(K34,7,4),MID(K34,4,2),LEFT(K34,2))+TIMEVALUE(RIGHT(K34,LEN(K34)-11)))-(DATE(MID(J34,7,4),MID(J34,4,2),LEFT(J34,2))+TIMEVALUE(RIGHT(J34,LEN(J34)-11))))*24 -> 75.683333 | Q34: =IF(F34<30,"Underutilized",IF(F34<70,"Normal","High")) -> Normal | R34: =IF(G34<40,"Underutilized",IF(G34<75,"Normal","High")) -> Normal | S34: =(H34+I34)/1073741824 -> 47.28247 | T34: =IF(O34>AVERAGE($O$2:$O$500),"High Cost","Normal Cost") -> High Cost | U34: =((F34+G34)/2)/(O34/100) -> 0.034349464
A35: res-2NWIUO2C | B35: Cloud Load Balancing | C35: 868.8778 | D35: Requests | E35: asia-east1 | F35: 72.08 | G35: 28.06 | H35: 13159648227 | I35: 16566379456 | J35: 14-07-2024 17:48 | K35: 16-07-2024 23:28 | L35: 2.33 | M35: 2024.49 | N35: 2024 | O35: 167992 | P35: =((DATE(MID(K35,7,4),MID(K35,4,2),LEFT(K35,2))+TIMEVALUE(RIGHT(K35,LEN(K35)-11)))-(DATE(MID(J35,7,4),MID(J35,4,2),LEFT(J35,2))+TIMEVALUE(RIGHT(J35,LEN(J35)-11))))*24 -> 53.666667 | Q35: =IF(F35<30,"Underutilized",IF(F35<70,"Normal","High")) -> High | R35: =IF(G35<40,"Underutilized",IF(G35<75,"Normal","High")) -> Underutilized | S35: =(H35+I35)/1073741824 -> 27.684521 | T35: =IF(O35>AVERAGE($O$2:$O$500),"High Cost","Normal Cost") -> Normal Cost | U35: =((F35+G35)/2)/(O35/100) -> 0.029804991
A36: res-TDYG7ESV | B36: Cloud NAT | C36: 306.7861 | D36: GB | E36: europe-north1 | F36: 19.59 | G36: 95.71 | H36: 98160908124 | I36: 106232000000 | J36: 45572.969 | K36: 45633.119 | L36: 8.51 | M36: 2610.75 | N36: 2611 | O36: 216713 | P36: =((DATE(MID(K36,7,4),MID(K36,4,2),LEFT(K36,2))+TIMEVALUE(RIGHT(K36,LEN(K36)-11)))-(DATE(MID(J36,7,4),MID(J36,4,2),LEFT(J36,2))+TIMEVALUE(RIGHT(J36,LEN(J36)-11))))*24 -> 27.6 | Q36: =IF(F36<30,"Underutilized",IF(F36<70,"Normal","High")) -> Underutilized | R36: =IF(G36<40,"Underutilized",IF(G36<75,"Normal","High")) -> High | S36: =(H36+I36)/1073741824 -> 190.35573 | T36: =IF(O36>AVERAGE($O$2:$O$500),"High Cost","Normal Cost") -> High Cost | U36: =((F36+G36)/2)/(O36/100) -> 0.026602004
A37: res-66L7XN4J | B37: AI Platform | C37: 31.9333 | D37: Hours | E37: europe-west1 | F37: 5.7 | G37: 31.59 | H37: 35137713111 | I37: 43813630384 | J37: 29-07-2024 06:08 | K37: 30-07-2024 14:04 | L37: 1.05 | M37: 33.53 | N37: 34 | O37: 2822 | P37: =((DATE(MID(K37,7,4),MID(K37,4,2),LEFT(K37,2))+TIMEVALUE(RIGHT(K37,LEN(K37)-11)))-(DATE(MID(J37,7,4),MID(J37,4,2),LEFT(J37,2))+TIMEVALUE(RIGHT(J37,LEN(J37)-11))))*24 -> 31.933333 | Q37: =IF(F37<30,"Underutilized",IF(F37<70,"Normal","High")) -> Underutilized | R37: =IF(G37<40,"Underutilized",IF(G37<75,"Normal","High")) -> Underutilized | S37: =(H37+I37)/1073741824 -> 73.529168 | T37: =IF(O37>AVERAGE($O$2:$O$500),"High Cost","Normal Cost") -> Normal Cost | U37: =((F37+G37)/2)/(O37/100) -> 0.66070163
A38: res-SG6WQFX8 | B38: Cloud Armor | C38: 715.0198 | D38: GB | E38: us-west1 | F38: 44.97 | G38: 13.16 | H38: 47790743712 | I38: 50699817640 | J38: 14-07-2024 09:21 | K38: 18-07-2024 20:13 | L38: 3.29 | M38: 2352.42 | N38: 2352 | O38: 195216 | P38: =((DATE(MID(K38,7,4),MID(K38,4,2),LEFT(K38,2))+TIMEVALUE(RIGHT(K38,LEN(K38)-11)))-(DATE(MID(J38,7,4),MID(J38,4,2),LEFT(J38,2))+TIMEVALUE(RIGHT(J38,LEN(J38)-11))))*24 -> 106.86667 | Q38: =IF(F38<30,"Underutilized",IF(F38<70,"Normal","High")) -> Normal | R38: =IF(G38<40,"Underutilized",IF(G38<75,"Normal","High")) -> Underutilized | S38: =(H38+I38)/1073741824 -> 91.726483 | T38: =IF(O38>AVERAGE($O$2:$O$500),"High Cost","Normal Cost") -> High Cost | U38: =((F38+G38)/2)/(O38/100) -> 0.014888636
A39: res-6EL50YPV | B39: Cloud CDN | C39: 749.8858 | D39: GB | E39: europe-north1 | F39: 84.06 | G39: 47.12 | H39: 58205533146 | I39: 63495177785 | J39: 16-08-2024 20:04 | K39: 21-08-2024 12:08 | L39: 2.03 | M39: 1522.27 | N39: 1522 | O39: 126326 | P39: =((DATE(MID(K39,7,4),MID(K39,4,2),LEFT(K39,2))+TIMEVALUE(RIGHT(K39,LEN(K39)-11)))-(DATE(MID(J39,7,4),MID(J39,4,2),LEFT(J39,2))+TIMEVALUE(RIGHT(J39,LEN(J39)-11))))*24 -> 112.06667 | Q39: =IF(F39<30,"Underutilized",IF(F39<70,"Normal","High")) -> High | R39: =IF(G39<40,"Underutilized",IF(G39<75,"Normal","High")) -> Normal | S39: =(H39+I39)/1073741824 -> 113.34262 | T39: =IF(O39>AVERAGE($O$2:$O$500),"High Cost","Normal Cost") -> Normal Cost | U39: =((F39+G39)/2)/(O39/100) -> 0.05192122
A40: res-ALHVTEHO | B40: Kubernetes Engine | C40: 110.3167 | D40: Hours | E40: us-east1 | F40: 49.67 | G40: 26.17 | H40: 79950895147 | I40: 87873607051 | J40: 45359.415 | K40: 45512.011 | L40: 7.61 | M40: 839.51 | N40: 840 | O40: 69720 | P40: =((DATE(MID(K40,7,4),MID(K40,4,2),LEFT(K40,2))+TIMEVALUE(RIGHT(K40,LEN(K40)-11)))-(DATE(MID(J40,7,4),MID(J40,4,2),LEFT(J40,2))+TIMEVALUE(RIGHT(J40,LEN(J40)-11))))*24 -> 110.31667 | Q40: =IF(F40<30,"Underutilized",IF(F40<70,"Normal","High")) -> Normal | R40: =IF(G40<40,"Underutilized",IF(G40<75,"Normal","High")) -> Underutilized | S40: =(H40+I40)/1073741824 -> 156.29875 | T40: =IF(O40>AVERAGE($O$2:$O$500),"High Cost","Normal Cost") -> Normal Cost | U40: =((F40+G40)/2)/(O40/100) -> 0.054388985
...

Sheet Pivot_Tables

Sheet Dashboard
A1: Google Cloud FinOps Cost Optimization Dashboard
A2: Total Spend | C2: Avg CPU Utilization | E2: Underutilized Resources | G2: High Cost Resources
A3: =SUM(Cleaned_Data!O2:O500) -> 86458195 | C3: =AVERAGE(Cleaned_Data!F2:F500) -> 52.21978 | E3: =COUNTIF(Cleaned_Data!Q2:Q500,"Underutilized") -> 132 | G3: =COUNTIF(Cleaned_Data!T2:T500,"High Cost") -> 178
